<mujoco model="rx200">
  <compiler angle="radian" meshdir="assets" texturedir="assets" autolimits="true" />
  <option integrator="implicitfast" cone="elliptic" impratio="10">
    <flag energy="enable"/>
  </option>
  <visual>
    <global fovy="45"/>
    <map force="0.1" torque="0.1"/>
    <scale forcewidth="0.01" contactwidth="0.05" contactheight="0.05"/>
  </visual>
  <asset>
    <texture type="2d" file="interbotix_black.png"/>
    <material name="black" texture="interbotix_black"/>

    <mesh name="rx200_1_base" file="rx200_1_base.stl" class="rx200"/>
    <mesh name="rx200_2_shoulder" file="rx200_2_shoulder.stl" class="rx200"/>
    <mesh name="rx200_3_upper_arm" file="rx200_3_upper_arm.stl" class="rx200"/>
    <mesh name="rx200_4_forearm" file="rx200_4_forearm.stl" class="rx200"/>
    <mesh name="rx200_5_wrist" file="rx200_5_wrist.stl" class="rx200"/>
    <mesh name="rx200_6_gripper" file="rx200_6_gripper.stl" class="rx200"/>
    <mesh name="rx200_7_gripper_prop" file="rx200_7_gripper_prop.stl" class="rx200"/>
    <mesh name="rx200_8_gripper_bar" file="rx200_8_gripper_bar.stl" class="rx200"/>
    <mesh name="rx200_9_gripper_finger" file="rx200_9_gripper_finger.stl" class="rx200"/>
  </asset>

  <default>
    <default class="rx200">
      <mesh scale="0.001 0.001 0.001"/>
      <joint axis="0 1 0" armature="0.1"/>

      <default class="waist">
        <joint axis="0 0 1" range="-3.14158 3.14158" actuatorfrcrange="-8 8"/>
        <position kp="800" kv="12" inheritrange="1" forcerange="-8 8"/>
      </default>

      <default class="shoulder">
        <joint axis="0 1 0" range="-1.88496 1.97222" actuatorfrcrange="-18 18"/>
        <position kp="900" kv="15" inheritrange="1" forcerange="-18 18"/>
      </default>

      <default class="elbow">
        <joint axis="0 1 0" range="-1.88496 1.62316" actuatorfrcrange="-13 13"/>
        <position kp="850" kv="14" inheritrange="1" forcerange="-13 13"/>
      </default>

      <default class="wrist_angle">
        <joint axis="0 1 0" range="-1.74533 2.14675" actuatorfrcrange="-5 5"/>
        <position kp="700" kv="10" inheritrange="1" forcerange="-5 5"/>
      </default>

      <default class="wrist_rotate">
        <joint axis="1 0 0" range="-3.14158 3.14158" actuatorfrcrange="-5 5"/>
        <position kp="650" kv="8" inheritrange="1" forcerange="-5 5"/>
      </default>

      <!-- 
      <default class="gripper">
        <joint axis="1 0 0" actuatorfrcrange="-1 1"/>
      </default>
      -->

      <default class="finger">
        <joint type="slide" axis="0 1 0" actuatorfrcrange="-5 5"/>
        <position kp="600" kv="6" inheritrange="1" forcerange="-5 5"/>
        <default class="left_finger">
          <joint range="0.015 0.037"/>
        </default>
        <default class="right_finger">
          <joint range="-0.037 -0.015"/>
        </default>
      </default>

      <default class="visual">
        <geom type="mesh" contype="0" conaffinity="0" density="0" group="2" material="black"/>
      </default>
      <default class="collision">
        <geom type="mesh" group="3"/>
      </default>
    </default>
  </default>

  <worldbody>
    <light mode="targetbodycom" target="rx200/gripper_link" pos="1 0 1"/>

    <body name="rx200/base_link" childclass="rx200">
      <inertial pos="-0.0354389 -0.00335861 0.0253408" quat="0.533728 0.464944 -0.496014 0.502923" mass="0.766135" diaginertia="0.00412697 0.00336074 0.00133329"/>
      <geom quat="0.707107 0 0 -0.707107" mesh="rx200_1_base" class="visual"/>
      <geom quat="0.707107 0 0 -0.707107" mesh="rx200_1_base" class="collision"/>

      <body name="rx200/shoulder_link" pos="0 0 0.06566">
        <inertial pos="-8.53644e-05 1.7369e-05 0.0132005" quat="0.00551577 0.707173 0.0055144 0.706997" mass="0.257774" diaginertia="0.000471107 0.000442793 0.0002663"/>
        <site name="waist_site" pos="0 0 0" size="0.001" rgba="1 0 0 1"/>
        <joint name="waist" class="waist"/>
        <geom pos="0 0 0.0015" quat="0.707107 0 0 -0.707107" mesh="rx200_2_shoulder" class="visual"/>
        <geom pos="0 0 0.0015" quat="0.707107 0 0 -0.707107" mesh="rx200_2_shoulder" class="collision"/>
        
        <body name="rx200/upper_arm_link" pos="0 0 0.03891">
          <inertial pos="0.0119513 -0.000116923 0.13943" quat="0.997528 0.0699303 -0.000209782 -0.00692919" mass="0.297782" diaginertia="0.00171001 0.00166103 0.000117759"/>
          <site name="shoulder_site" pos="0 0 0" size="0.001" rgba="0 1 0 1"/>
          <joint name="shoulder" class="shoulder"/>
          <geom quat="0.707107 0 0 0.707107" mesh="rx200_3_upper_arm" class="visual"/>
          <geom quat="0.707107 0 0 0.707107" mesh="rx200_3_upper_arm" class="collision"/>
          
          <body name="rx200/forearm_link" pos="0.05 0 0.2">
            <inertial pos="0.114745 -9.38376e-05 0" quat="0.500461 0.499538 -0.500461 0.499538" mass="0.258863" diaginertia="0.001076 0.001055 6.42066e-05"/>
            <site name="elbow_site" pos="0 0 0" size="0.001" rgba="0 0 1 1"/>
            <joint name="elbow" class="elbow"/>
            <geom quat="0.707107 0 0 0.707107" mesh="rx200_4_forearm" class="visual"/>
            <geom quat="0.707107 0 0 0.707107" mesh="rx200_4_forearm" class="collision"/>

            <body name="rx200/wrist_link" pos="0.2 0 0">
              <inertial pos="0.04236 -1.0411e-05 0.010577" quat="0.608721 0.363497 -0.359175 0.606895" mass="0.084957" diaginertia="3.29057e-05 3.082e-05 2.68343e-05"/>
              <site name="wrist_angle_site" pos="0 0 0" size="0.001" rgba="1 1 0 1"/>
              <joint name="wrist_angle" class="wrist_angle"/>
              <geom quat="0.707107 0 0 0.707107" mesh="rx200_5_wrist" class="visual"/>
              <geom quat="0.707107 0 0 0.707107" mesh="rx200_5_wrist" class="collision"/>

              <body name="rx200/gripper_link" pos="0.065 0 0">
                <inertial pos="0.02163 0 0.01141" quat="0.992449 0.12266 0 0" mass="0.072885" diaginertia="2.537e-05 1.84689e-05 1.66311e-05"/>
                <site name="wrist_rotate_site" pos="0 0 0" size="0.001" rgba="1 0 1 1"/>
                <joint name="wrist_rotate" class="wrist_rotate"/>
                <geom pos="-0.02 0 0" quat="0.707107 0 0 0.707107" mesh="rx200_6_gripper" class="visual"/>
                <geom pos="-0.02 0 0" quat="0.707107 0 0 0.707107" mesh="rx200_6_gripper" class="collision"/>

                <body name="rx200/ee_arm_link" pos="0.043 0 0">
                  <inertial pos="0 0 0" mass="0.001" diaginertia="0.001 0.001 0.001"/>

                  <body name="rx200/gripper_prop_link" pos="0.0055 0 0">
                    <inertial pos="0.000846 -1.933e-06 4.2e-05" quat="0.654786 -0.266277 -0.265707 0.655555" mass="0.00434" diaginertia="1.1156e-06 9.02926e-07 2.63673e-07"/>
					
                    <!-- <joint name="gripper" class="gripper"/> -->
                    <geom pos="-0.0685 0 0" quat="0.707107 0 0 0.707107" mesh="rx200_7_gripper_prop" class="visual"/>
                    <geom pos="-0.0685 0 0" quat="0.707107 0 0 0.707107" mesh="rx200_7_gripper_prop" class="collision"/>
                  </body>

                  <body name="rx200/gripper_bar_link">
                    <inertial pos="0.009687 5.66e-07 0.004962" quat="-0.260601 0.657335 -0.260567 0.657345" mass="0.034199" diaginertia="2.99065e-05 2.71235e-05 7.4125e-06"/>
                    <geom pos="-0.063 0 0" quat="0.707107 0 0 0.707107" mesh="rx200_8_gripper_bar" class="visual"/>
                    <geom pos="-0.063 0 0" quat="0.707107 0 0 0.707107" mesh="rx200_8_gripper_bar" class="collision"/>

                    <body name="rx200/fingers_link" pos="0.023 0 0">
                      <inertial pos="0 0 0" mass="0.001" diaginertia="0.001 0.001 0.001"/>

                      <body name="rx200/left_finger_link">
                        <inertial pos="0.013816 0 0" quat="0.705384 0.705384 -0.0493271 -0.0493271" mass="0.016246" diaginertia="4.79509e-06 3.7467e-06 1.48651e-06"/>
                        <site name="left_finger_site" pos="0 0 0" size="0.001" rgba="0 1 1 1"/>
                        <joint name="left_finger" class="left_finger"/>
                        <geom pos="0 0.005 0" quat="0 0 0 -1" mesh="rx200_9_gripper_finger" class="visual"/>
                        <geom pos="0 0.005 0" quat="0 0 0 -1" mesh="rx200_9_gripper_finger" class="collision"/>
                      </body>

                      <body name="rx200/right_finger_link">
                        <inertial pos="0.013816 0 0" quat="0.705384 0.705384 0.0493271 0.0493271" mass="0.016246" diaginertia="4.79509e-06 3.7467e-06 1.48651e-06"/>
                        <site name="right_finger_site" pos="0 0 0" size="0.001" rgba="0 1 1 1"/>
                        <joint name="right_finger" class="right_finger"/>
                        <geom pos="0 -0.005 0" quat="0 0 1 0" mesh="rx200_9_gripper_finger" class="visual"/>
                        <geom pos="0 -0.005 0" quat="0 0 1 0" mesh="rx200_9_gripper_finger" class="collision"/>
                      </body>

                      <body name="rx200/ee_gripper_link" pos="0.027575 0 0">
                        <inertial pos="0 0 0" mass="0.001" diaginertia="0.001 0.001 0.001"/>
                      </body>

                    </body>
                  </body>
                </body>
              </body>
            </body>
          </body>
        </body>
      </body>
    </body>
  </worldbody>

  <contact>
    <exclude body1="rx200/base_link" body2="rx200/shoulder_link"/>
  </contact>

  <equality>
    <joint joint1="left_finger" joint2="right_finger" polycoef="0 -1 0 0 0"/>
  </equality>

  <keyframe>
    <key name="home" qpos="0 0 0 0 0 0.015 -0.015" ctrl="0 0 0 0 0 0.015"/>
  </keyframe>

  <actuator>
    <position class="waist" joint="waist"/>
    <position class="shoulder" joint="shoulder"/>
    <position class="elbow" joint="elbow"/>
    <position class="wrist_angle" joint="wrist_angle"/>
    <position class="wrist_rotate" joint="wrist_rotate"/>
    <position class="left_finger" joint="left_finger"/>
  </actuator>

  <sensor>
    <torque site="waist_site"/>
    <torque site="shoulder_site"/>
    <torque site="elbow_site"/>
    <torque site="wrist_angle_site"/>
    <torque site="wrist_rotate_site"/>
    <force site="left_finger_site"/>
    <force site="right_finger_site"/>
  </sensor>

</mujoco>
